<?xml version="1.0"?>
<robot name="girona500" xmlns:xacro="http://www.ros.org/wiki/xacro">

  <!-- Import all Gazebo-customization elements, including Gazebo colors -->
  <xacro:include filename="$(find g500arm5_description)/urdf/g500arm5.gazebo" />
  <!-- Import Rviz colors -->
  <xacro:include filename="$(find g500arm5_description)/urdf/materials.xacro" />

  <link name="base_link">
    <visual>
      <origin rpy="1.57079 0 3.1416" xyz="0 0 0"/>
      <geometry>
        <mesh filename="package://g500arm5_description/meshes/GIRONA500/g500.dae"/>
      </geometry>
    </visual>
    <collision>
      <geometry>
        <cylinder length="1.5" radius="0.35"/>
      </geometry>
    </collision>
    <inertial>
      <mass value="98"/>
      <inertia ixx="8.0" ixy="0.0" ixz="0.0" 
                         iyy="8.0" iyz="0.0" 
                                   izz="8.0"/>
    </inertial>          
  </link>  

  <link name="part0">
    <visual>
      <origin rpy="0.0 0 0" xyz="0 0 0"/>
      <geometry>
        <mesh filename="package://g500arm5_description/meshes/ARM5E/ARM5E_part0.dae"/>
      </geometry>
    </visual>
    <collision>
      <geometry>
        <box size="0.35 0.13 0.10" />
      </geometry>
    </collision>
    <inertial>
      <mass value="0.01"/>
      <inertia ixx="6.667e-7" ixy="0.0"       ixz="0.0"
                              iyy="6.667e-7"  iyz="0.0"
                                              izz="6.667e-7" />
    </inertial>
  </link>


  <joint name="baselink_to_part0" type="fixed">
    <parent link="base_link"/>
    <child link="part0"/>
    <origin rpy="0 0 0" xyz="-0.2 0 -.2"/>
  </joint>

  <link name="part1">
    <visual>
      <origin rpy="0 0 0" xyz="0.0 0 0"/>
      <geometry>
        <mesh filename="package://g500arm5_description/meshes/ARM5E/ARM5E_part1.dae"/>
      </geometry>
    </visual>
    <collision>
      <geometry>
        <box size="0.10 0.16 0.15" />
      </geometry>
    </collision>
    <inertial>
      <mass value="0.01"/>
      <inertia ixx="6.667e-7" ixy="0.0"       ixz="0.0"
                              iyy="6.667e-7"  iyz="0.0"
                                              izz="6.667e-7" />
    </inertial>
  </link>

  <joint name="part0_to_part1" type="continuous">
    <parent link="part0"/>
    <child link="part1"/>
    <axis xyz="0 0 -1"/>
    <origin rpy="0 0 1.57" xyz="0 0 0"/>    
    <dynamics damping="0.5"/>
  </joint>

  <link name="part2">
    <visual>
      <origin rpy="0 -0.209 0" xyz="0 0 0"/>
      <geometry>
        <mesh filename="package://g500arm5_description/meshes/ARM5E/ARM5E_part2.dae"/>
      </geometry>
    </visual>
    <collision>
      <geometry>
        <box size="0.60 0.15 0.20" />
      </geometry>
    </collision>
    <inertial>
      <mass value="0.01"/>
      <inertia ixx="6.667e-7" ixy="0.0"       ixz="0.0"
                              iyy="6.667e-7"  iyz="0.0"
                                              izz="6.667e-7" />
    </inertial>
  </link>

  <joint name="part1_to_part2" type="continuous">
    <parent link="part1"/>
    <child link="part2"/>
    <axis xyz="0 1 0"/>
    <origin rpy="0 0.209 0" xyz="0.077 0 -0.130"/>
    <dynamics damping="0.5"/>
  </joint>

  <link name="part3">
    <visual>
      <origin rpy="0 0 0" xyz="0 0 0"/>
      <geometry>
        <mesh filename="package://g500arm5_description/meshes/ARM5E/ARM5E_part3.stl"/>
      </geometry>
    </visual>
    <collision>
      <geometry>
        <box size="0.35 0.25 0.15" />
      </geometry>
    </collision>
    <inertial>
      <mass value="0.01"/>
      <inertia ixx="6.667e-7" ixy="0.0"      ixz="0.0"
                              iyy="6.667e-7" iyz="0.0"
                                             izz="6.667e-7" />
    </inertial>
  </link>

  <joint name="part2_to_part3" type="continuous">
    <parent link="part2"/>
    <child link="part3"/>
    <axis xyz="0 1 0"/>
    <origin rpy=" 0 0.262 0 " xyz="0.44278 0 0"/>
    <dynamics damping="0.5"/>
  </joint>

  <link name="part4_base">
    <visual>
      <origin rpy="0 0 0" xyz="0 0 0"/>
      <geometry>
        <mesh filename="package://g500arm5_description/meshes/ARM5E/ARM5E_part4_base.dae"/>
      </geometry>
    </visual>
    <collision>
      <geometry>
        <box size="0.10 0.10 0.10" />
      </geometry>
    </collision>
    <inertial>
      <mass value="0.01"/>
      <inertia ixx="6.667e-7" ixy="0.0"       ixz="0.0"
                              iyy="6.667e-7"  iyz="0.0"
                                              izz="6.667e-7" />
    </inertial>
  </link>

  <joint name="part3_to_part4_base" type="continuous">
    <parent link="part3"/>
    <child link="part4_base"/>
    <axis xyz="1 0 0"/>
    <origin rpy="0 0 0" xyz="0.320 0 0.077 "/>
    <dynamics damping="0.5"/>
  </joint>
  
  <link name="part4_jaw1">
    <visual>
      <origin rpy="0 0 0" xyz="0 0 0"/>
      <geometry>
        <mesh filename="package://g500arm5_description/meshes/ARM5E/ARM5E_part4_jaw1.dae"/>
      </geometry>
    </visual>
    <collision>
      <geometry>
        <mesh filename="package://g500arm5_description/meshes/ARM5E/ARM5E_part4_jaw1.dae"/>
      </geometry>
    </collision>
    <inertial>
      <mass value="0.01"/>
      <inertia ixx="6.667e-7" ixy="0.0"       ixz="0.0"
                              iyy="6.667e-7"  iyz="0.0"
                                              izz="6.667e-7" />
    </inertial>
  </link>
  
  <joint name="part4_to_part4_jaw1" type="continuous">
    <parent link="part4_base"/>
    <child link="part4_jaw1"/>
    <axis xyz="0 -1 0"/>
    <origin rpy="0 0 0" xyz="0.07 0 0.04"/>
    <dynamics damping="0.5"/>
  </joint>

  <link name="part4_jaw2">
    <visual>
      <origin rpy="0 0 0" xyz="0 0 0"/>
      <geometry>
        <mesh filename="package://g500arm5_description/meshes/ARM5E/ARM5E_part4_jaw2.dae"/>
      </geometry>
    </visual>
    <collision>
      <geometry>
        <mesh filename="package://g500arm5_description/meshes/ARM5E/ARM5E_part4_jaw2.dae"/>
      </geometry>
    </collision>
    <inertial>
      <mass value="0.01"/>
      <inertia ixx="6.667e-7" ixy="0.0"       ixz="0.0"
                              iyy="6.667e-7"  iyz="0.0"
                                              izz="6.667e-7" />
    </inertial>
  </link>

  <joint name="part4_to_part4_jaw2" type="continuous">
    <parent link="part4_base"/>
    <child link="part4_jaw2"/>
    <axis xyz="0 1 0"/>
    <origin rpy="0 0 0" xyz="0.07 0 -0.04"/>
    <mimic joint="part4_to_part4_jaw1" multiplier="1" offset="0"/>    
  </joint>

</robot>
